Workbook

Sheet How to use
A1: HRMS Portal - QA Test Case Sheet
A2: Scope: HRMS only (auth, employees, org setup, attendance, WFH, leave, comp-off, payroll). LMS/course features are not covered.
A3: Built from the code of rahul52us/hrms-portal-new-backend and rahul52us/hrms-portal-new-frontend (rules, validation messages and existing unit tests).
A5: How to use
A6: 1. Go to the 'Test Cases' sheet. Cells with a yellow header (Status, Actual Result, Tester, Date, Bug ID) are the ones you fill in. Everything else is the test design.
A7: 2. Follow 'Steps' using 'Test Data', then compare with 'Expected Result'. Set Status to Pass / Fail / Blocked / N/A.
A8: 3. On Fail, write what actually happened in 'Actual Result' and add the bug id.
A9: 4. The 'Summary' sheet updates automatically from the Status column.
A10: 5. Numbers marked '(per fixture)' or based on a policy value (e.g. WFH limit 2/week) need the same configuration in your test environment.
A12: Legend
A13: Type: Positive = happy path | Negative = should be refused | Validation = field rules | Boundary = limit values | Edge = unusual situation | Permission = role/access | UI = screen behaviour
A14: Priority: P0 = release blocker | P1 = high | P2 = medium | P3 = low
... A17: Example of a filled row
A18: TC ID | B18: Scenario | C18: Status | D18: Actual Result | E18: Tester | F18: Date | G18: Bug ID
A19: AUTH-003 | B19: Wrong password | C19: Fail | D19: Login succeeded with a wrong password | E19: Priya | F19: 2026-10-22 | G19: BUG-101
A21: Status note: rows marked Pass by 'Claude (auto)' were verified by running the backend logic only (calculators, validators, rules). Screens, API calls and database flows could not be run in that environment and are still 'Not Run'.

Sheet Summary
A1: Execution summary
A3: Module | B3: Total | C3: Pass | D3: Fail | E3: Blocked | F3: N/A | G3: Not Run | H3: % Executed | I3: P0 cases | J3: P0 not passed
A4: Authentication | B4: =COUNTIF('Test Cases'!$B$2:$B$287,$A4) -> 40 | C4: =COUNTIFS('Test Cases'!$B$2:$B$287,$A4,'Test Cases'!$M$2:$M$287,"Pass") -> 3 | D4: =COUNTIFS('Test Cases'!$B$2:$B$287,$A4,'Test Cases'!$M$2:$M$287,"Fail") -> 0 | E4: =COUNTIFS('Test Cases'!$B$2:$B$287,$A4,'Test Cases'!$M$2:$M$287,"Blocked") -> 0 | F4: =COUNTIFS('Test Cases'!$B$2:$B$287,$A4,'Test Cases'!$M$2:$M$287,"N/A") -> 0 | G4: =COUNTIFS('Test Cases'!$B$2:$B$287,$A4,'Test Cases'!$M$2:$M$287,"Not Run") -> 37 | H4: =IF(B4=0,0,(B4-G4)/B4) -> 0.075 | I4: =COUNTIFS('Test Cases'!$B$2:$B$287,$A4,'Test Cases'!$F$2:$F$287,"P0") -> 10 | J4: =I4-COUNTIFS('Test Cases'!$B$2:$B$287,$A4,'Test Cases'!$F$2:$F$287,"P0",'Test Cases'!$M$2:$M$287,"Pass") -> 7
A5: Employees & Users | B5: =COUNTIF('Test Cases'!$B$2:$B$287,$A5) -> 30 | C5: =COUNTIFS('Test Cases'!$B$2:$B$287,$A5,'Test Cases'!$M$2:$M$287,"Pass") -> 8 | D5: =COUNTIFS('Test Cases'!$B$2:$B$287,$A5,'Test Cases'!$M$2:$M$287,"Fail") -> 0 | E5: =COUNTIFS('Test Cases'!$B$2:$B$287,$A5,'Test Cases'!$M$2:$M$287,"Blocked") -> 0 | F5: =COUNTIFS('Test Cases'!$B$2:$B$287,$A5,'Test Cases'!$M$2:$M$287,"N/A") -> 0 | G5: =COUNTIFS('Test Cases'!$B$2:$B$287,$A5,'Test Cases'!$M$2:$M$287,"Not Run") -> 22 | H5: =IF(B5=0,0,(B5-G5)/B5) -> 0.26666667 | I5: =COUNTIFS('Test Cases'!$B$2:$B$287,$A5,'Test Cases'!$F$2:$F$287,"P0") -> 5 | J5: =I5-COUNTIFS('Test Cases'!$B$2:$B$287,$A5,'Test Cases'!$F$2:$F$287,"P0",'Test Cases'!$M$2:$M$287,"Pass") -> 5
A6: Employee Profile | B6: =COUNTIF('Test Cases'!$B$2:$B$287,$A6) -> 10 | C6: =COUNTIFS('Test Cases'!$B$2:$B$287,$A6,'Test Cases'!$M$2:$M$287,"Pass") -> 0 | D6: =COUNTIFS('Test Cases'!$B$2:$B$287,$A6,'Test Cases'!$M$2:$M$287,"Fail") -> 0 | E6: =COUNTIFS('Test Cases'!$B$2:$B$287,$A6,'Test Cases'!$M$2:$M$287,"Blocked") -> 0 | F6: =COUNTIFS('Test Cases'!$B$2:$B$287,$A6,'Test Cases'!$M$2:$M$287,"N/A") -> 0 | G6: =COUNTIFS('Test Cases'!$B$2:$B$287,$A6,'Test Cases'!$M$2:$M$287,"Not Run") -> 10 | H6: =IF(B6=0,0,(B6-G6)/B6) -> 0 | I6: =COUNTIFS('Test Cases'!$B$2:$B$287,$A6,'Test Cases'!$F$2:$F$287,"P0") -> 1 | J6: =I6-COUNTIFS('Test Cases'!$B$2:$B$287,$A6,'Test Cases'!$F$2:$F$287,"P0",'Test Cases'!$M$2:$M$287,"Pass") -> 1
A7: Roles & Permissions | B7: =COUNTIF('Test Cases'!$B$2:$B$287,$A7) -> 7 | C7: =COUNTIFS('Test Cases'!$B$2:$B$287,$A7,'Test Cases'!$M$2:$M$287,"Pass") -> 4 | D7: =COUNTIFS('Test Cases'!$B$2:$B$287,$A7,'Test Cases'!$M$2:$M$287,"Fail") -> 0 | E7: =COUNTIFS('Test Cases'!$B$2:$B$287,$A7,'Test Cases'!$M$2:$M$287,"Blocked") -> 0 | F7: =COUNTIFS('Test Cases'!$B$2:$B$287,$A7,'Test Cases'!$M$2:$M$287,"N/A") -> 0 | G7: =COUNTIFS('Test Cases'!$B$2:$B$287,$A7,'Test Cases'!$M$2:$M$287,"Not Run") -> 3 | H7: =IF(B7=0,0,(B7-G7)/B7) -> 0.57142857 | I7: =COUNTIFS('Test Cases'!$B$2:$B$287,$A7,'Test Cases'!$F$2:$F$287,"P0") -> 2 | J7: =I7-COUNTIFS('Test Cases'!$B$2:$B$287,$A7,'Test Cases'!$F$2:$F$287,"P0",'Test Cases'!$M$2:$M$287,"Pass") -> 2
A8: Organization Setup | B8: =COUNTIF('Test Cases'!$B$2:$B$287,$A8) -> 20 | C8: =COUNTIFS('Test Cases'!$B$2:$B$287,$A8,'Test Cases'!$M$2:$M$287,"Pass") -> 0 | D8: =COUNTIFS('Test Cases'!$B$2:$B$287,$A8,'Test Cases'!$M$2:$M$287,"Fail") -> 0 | E8: =COUNTIFS('Test Cases'!$B$2:$B$287,$A8,'Test Cases'!$M$2:$M$287,"Blocked") -> 0 | F8: =COUNTIFS('Test Cases'!$B$2:$B$287,$A8,'Test Cases'!$M$2:$M$287,"N/A") -> 0 | G8: =COUNTIFS('Test Cases'!$B$2:$B$287,$A8,'Test Cases'!$M$2:$M$287,"Not Run") -> 20 | H8: =IF(B8=0,0,(B8-G8)/B8) -> 0 | I8: =COUNTIFS('Test Cases'!$B$2:$B$287,$A8,'Test Cases'!$F$2:$F$287,"P0") -> 2 | J8: =I8-COUNTIFS('Test Cases'!$B$2:$B$287,$A8,'Test Cases'!$F$2:$F$287,"P0",'Test Cases'!$M$2:$M$287,"Pass") -> 2
A9: Attendance | B9: =COUNTIF('Test Cases'!$B$2:$B$287,$A9) -> 40 | C9: =COUNTIFS('Test Cases'!$B$2:$B$287,$A9,'Test Cases'!$M$2:$M$287,"Pass") -> 14 | D9: =COUNTIFS('Test Cases'!$B$2:$B$287,$A9,'Test Cases'!$M$2:$M$287,"Fail") -> 0 | E9: =COUNTIFS('Test Cases'!$B$2:$B$287,$A9,'Test Cases'!$M$2:$M$287,"Blocked") -> 0 | F9: =COUNTIFS('Test Cases'!$B$2:$B$287,$A9,'Test Cases'!$M$2:$M$287,"N/A") -> 0 | G9: =COUNTIFS('Test Cases'!$B$2:$B$287,$A9,'Test Cases'!$M$2:$M$287,"Not Run") -> 26 | H9: =IF(B9=0,0,(B9-G9)/B9) -> 0.35 | I9: =COUNTIFS('Test Cases'!$B$2:$B$287,$A9,'Test Cases'!$F$2:$F$287,"P0") -> 8 | J9: =I9-COUNTIFS('Test Cases'!$B$2:$B$287,$A9,'Test Cases'!$F$2:$F$287,"P0",'Test Cases'!$M$2:$M$287,"Pass") -> 4
A10: Remote Work (WFH) | B10: =COUNTIF('Test Cases'!$B$2:$B$287,$A10) -> 12 | C10: =COUNTIFS('Test Cases'!$B$2:$B$287,$A10,'Test Cases'!$M$2:$M$287,"Pass") -> 4 | D10: =COUNTIFS('Test Cases'!$B$2:$B$287,$A10,'Test Cases'!$M$2:$M$287,"Fail") -> 0 | E10: =COUNTIFS('Test Cases'!$B$2:$B$287,$A10,'Test Cases'!$M$2:$M$287,"Blocked") -> 0 | F10: =COUNTIFS('Test Cases'!$B$2:$B$287,$A10,'Test Cases'!$M$2:$M$287,"N/A") -> 0 | G10: =COUNTIFS('Test Cases'!$B$2:$B$287,$A10,'Test Cases'!$M$2:$M$287,"Not Run") -> 8 | H10: =IF(B10=0,0,(B10-G10)/B10) -> 0.33333333 | I10: =COUNTIFS('Test Cases'!$B$2:$B$287,$A10,'Test Cases'!$F$2:$F$287,"P0") -> 2 | J10: =I10-COUNTIFS('Test Cases'!$B$2:$B$287,$A10,'Test Cases'!$F$2:$F$287,"P0",'Test Cases'!$M$2:$M$287,"Pass") -> 2
A11: Calendar & Workforce Policy | B11: =COUNTIF('Test Cases'!$B$2:$B$287,$A11) -> 8 | C11: =COUNTIFS('Test Cases'!$B$2:$B$287,$A11,'Test Cases'!$M$2:$M$287,"Pass") -> 0 | D11: =COUNTIFS('Test Cases'!$B$2:$B$287,$A11,'Test Cases'!$M$2:$M$287,"Fail") -> 0 | E11: =COUNTIFS('Test Cases'!$B$2:$B$287,$A11,'Test Cases'!$M$2:$M$287,"Blocked") -> 0 | F11: =COUNTIFS('Test Cases'!$B$2:$B$287,$A11,'Test Cases'!$M$2:$M$287,"N/A") -> 0 | G11: =COUNTIFS('Test Cases'!$B$2:$B$287,$A11,'Test Cases'!$M$2:$M$287,"Not Run") -> 8 | H11: =IF(B11=0,0,(B11-G11)/B11) -> 0 | I11: =COUNTIFS('Test Cases'!$B$2:$B$287,$A11,'Test Cases'!$F$2:$F$287,"P0") -> 0 | J11: =I11-COUNTIFS('Test Cases'!$B$2:$B$287,$A11,'Test Cases'!$F$2:$F$287,"P0",'Test Cases'!$M$2:$M$287,"Pass") -> 0
A12: Leave | B12: =COUNTIF('Test Cases'!$B$2:$B$287,$A12) -> 40 | C12: =COUNTIFS('Test Cases'!$B$2:$B$287,$A12,'Test Cases'!$M$2:$M$287,"Pass") -> 15 | D12: =COUNTIFS('Test Cases'!$B$2:$B$287,$A12,'Test Cases'!$M$2:$M$287,"Fail") -> 0 | E12: =COUNTIFS('Test Cases'!$B$2:$B$287,$A12,'Test Cases'!$M$2:$M$287,"Blocked") -> 0 | F12: =COUNTIFS('Test Cases'!$B$2:$B$287,$A12,'Test Cases'!$M$2:$M$287,"N/A") -> 0 | G12: =COUNTIFS('Test Cases'!$B$2:$B$287,$A12,'Test Cases'!$M$2:$M$287,"Not Run") -> 25 | H12: =IF(B12=0,0,(B12-G12)/B12) -> 0.375 | I12: =COUNTIFS('Test Cases'!$B$2:$B$287,$A12,'Test Cases'!$F$2:$F$287,"P0") -> 8 | J12: =I12-COUNTIFS('Test Cases'!$B$2:$B$287,$A12,'Test Cases'!$F$2:$F$287,"P0",'Test Cases'!$M$2:$M$287,"Pass") -> 7
A13: Comp-Off | B13: =COUNTIF('Test Cases'!$B$2:$B$287,$A13) -> 11 | C13: =COUNTIFS('Test Cases'!$B$2:$B$287,$A13,'Test Cases'!$M$2:$M$287,"Pass") -> 9 | D13: =COUNTIFS('Test Cases'!$B$2:$B$287,$A13,'Test Cases'!$M$2:$M$287,"Fail") -> 0 | E13: =COUNTIFS('Test Cases'!$B$2:$B$287,$A13,'Test Cases'!$M$2:$M$287,"Blocked") -> 0 | F13: =COUNTIFS('Test Cases'!$B$2:$B$287,$A13,'Test Cases'!$M$2:$M$287,"N/A") -> 0 | G13: =COUNTIFS('Test Cases'!$B$2:$B$287,$A13,'Test Cases'!$M$2:$M$287,"Not Run") -> 2 | H13: =IF(B13=0,0,(B13-G13)/B13) -> 0.81818182 | I13: =COUNTIFS('Test Cases'!$B$2:$B$287,$A13,'Test Cases'!$F$2:$F$287,"P0") -> 1 | J13: =I13-COUNTIFS('Test Cases'!$B$2:$B$287,$A13,'Test Cases'!$F$2:$F$287,"P0",'Test Cases'!$M$2:$M$287,"Pass") -> 0
A14: Payroll - Setup | B14: =COUNTIF('Test Cases'!$B$2:$B$287,$A14) -> 16 | C14: =COUNTIFS('Test Cases'!$B$2:$B$287,$A14,'Test Cases'!$M$2:$M$287,"Pass") -> 5 | D14: =COUNTIFS('Test Cases'!$B$2:$B$287,$A14,'Test Cases'!$M$2:$M$287,"Fail") -> 0 | E14: =COUNTIFS('Test Cases'!$B$2:$B$287,$A14,'Test Cases'!$M$2:$M$287,"Blocked") -> 0 | F14: =COUNTIFS('Test Cases'!$B$2:$B$287,$A14,'Test Cases'!$M$2:$M$287,"N/A") -> 0 | G14: =COUNTIFS('Test Cases'!$B$2:$B$287,$A14,'Test Cases'!$M$2:$M$287,"Not Run") -> 11 | H14: =IF(B14=0,0,(B14-G14)/B14) -> 0.3125 | I14: =COUNTIFS('Test Cases'!$B$2:$B$287,$A14,'Test Cases'!$F$2:$F$287,"P0") -> 4 | J14: =I14-COUNTIFS('Test Cases'!$B$2:$B$287,$A14,'Test Cases'!$F$2:$F$287,"P0",'Test Cases'!$M$2:$M$287,"Pass") -> 3
A15: Payroll - Calculation | B15: =COUNTIF('Test Cases'!$B$2:$B$287,$A15) -> 22 | C15: =COUNTIFS('Test Cases'!$B$2:$B$287,$A15,'Test Cases'!$M$2:$M$287,"Pass") -> 14 | D15: =COUNTIFS('Test Cases'!$B$2:$B$287,$A15,'Test Cases'!$M$2:$M$287,"Fail") -> 0 | E15: =COUNTIFS('Test Cases'!$B$2:$B$287,$A15,'Test Cases'!$M$2:$M$287,"Blocked") -> 0 | F15: =COUNTIFS('Test Cases'!$B$2:$B$287,$A15,'Test Cases'!$M$2:$M$287,"N/A") -> 0 | G15: =COUNTIFS('Test Cases'!$B$2:$B$287,$A15,'Test Cases'!$M$2:$M$287,"Not Run") -> 8 | H15: =IF(B15=0,0,(B15-G15)/B15) -> 0.63636364 | I15: =COUNTIFS('Test Cases'!$B$2:$B$287,$A15,'Test Cases'!$F$2:$F$287,"P0") -> 2 | J15: =I15-COUNTIFS('Test Cases'!$B$2:$B$287,$A15,'Test Cases'!$F$2:$F$287,"P0",'Test Cases'!$M$2:$M$287,"Pass") -> 1
... A17: Payroll - Payslips & Reports | B17: =COUNTIF('Test Cases'!$B$2:$B$287,$A17) -> 10 | C17: =COUNTIFS('Test Cases'!$B$2:$B$287,$A17,'Test Cases'!$M$2:$M$287,"Pass") -> 1 | D17: =COUNTIFS('Test Cases'!$B$2:$B$287,$A17,'Test Cases'!$M$2:$M$287,"Fail") -> 0 | E17: =COUNTIFS('Test Cases'!$B$2:$B$287,$A17,'Test Cases'!$M$2:$M$287,"Blocked") -> 0 | F17: =COUNTIFS('Test Cases'!$B$2:$B$287,$A17,'Test Cases'!$M$2:$M$287,"N/A") -> 0 | G17: =COUNTIFS('Test Cases'!$B$2:$B$287,$A17,'Test Cases'!$M$2:$M$287,"Not Run") -> 9 | H17: =IF(B17=0,0,(B17-G17)/B17) -> 0.1 | I17: =COUNTIFS('Test Cases'!$B$2:$B$287,$A17,'Test Cases'!$F$2:$F$287,"P0") -> 3 | J17: =I17-COUNTIFS('Test Cases'!$B$2:$B$287,$A17,'Test Cases'!$F$2:$F$287,"P0",'Test Cases'!$M$2:$M$287,"Pass") -> 3
A18: Total | B18: =SUM(B4:B17) -> 286 | C18: =SUM(C4:C17) -> 77 | D18: =SUM(D4:D17) -> 0 | E18: =SUM(E4:E17) -> 0 | F18: =SUM(F4:F17) -> 0 | G18: =SUM(G4:G17) -> 209 | H18: =IF(B18=0,0,(B18-G18)/B18) -> 0.26923077 | I18: =SUM(I4:I17) -> 57 | J18: =SUM(J4:J17) -> 46
A20: Counts update from the Status column of 'Test Cases'. Priority: P0 release blocker.

Sheet Test Cases
A1: TC ID | B1: Module | C1: Sub-module | D1: Scenario | E1: Type | F1: Priority | G1: Role | H1: Preconditions | I1: Steps | J1: Test Data | K1: Expected Result | L1: Source | M1: Status | N1: Actual Result | O1: Tester | P1: Date | Q1: Bug ID
A2: AUTH-001 | B2: Authentication | C2: Login | D2: Login with valid email and password | E2: Positive | F2: P0 | G2: Employee | H2: Active user exists (password set, enabled) | I2: 1. Open /login 2. Enter email 3. Enter password 4. Click Sign In | J2: admin@company.com / Test@1234 | K2: User is logged in and lands on the dashboard; token/session is created. | L2: backend src/services/auth/utils/validation.ts | M2: Not Run
A3: AUTH-002 | B3: Authentication | C3: Login | D3: Email is trimmed and lower-cased before login | E3: Positive | F3: P2 | G3: Employee | H3: Active user exists | I3: 1. Open /login 2. Enter email with spaces and capitals 3. Enter correct password 4. Sign In | J3: ' Admin@Company.COM ' / Test@1234 | K3: Login succeeds; username is treated as admin@company.com. | L3: backend src/services/auth/utils/validation.ts | M3: Not Run
A4: AUTH-003 | B4: Authentication | C4: Login | D4: Wrong password | E4: Negative | F4: P0 | G4: Anonymous | H4: Active user exists | I4: 1. Open /login 2. Enter valid email and wrong password 3. Sign In | J4: admin@company.com / Wrong@1234 | K4: Login rejected with an invalid-credentials error; no session created. | L4: backend src/services/auth/auth.service.ts | M4: Not Run
A5: AUTH-004 | B5: Authentication | C5: Login | D5: Unregistered email | E5: Negative | F5: P1 | G5: Anonymous | H5: Email not in system | I5: 1. Open /login 2. Enter unknown email and any password 3. Sign In | J5: nobody@nowhere.com / Test@1234 | K5: Login rejected; message does not reveal whether the email exists. | L5: backend src/services/auth/auth.service.ts | M5: Not Run
A6: AUTH-005 | B6: Authentication | C6: Login | D6: Empty email | E6: Validation | F6: P1 | G6: Anonymous | H6: - | I6: 1. Open /login 2. Leave email empty 3. Enter password 4. Sign In | J6: email='' / Test@1234 | K6: Error 'Username is required'; request not accepted. | L6: backend src/services/auth/utils/validation.ts | M6: Not Run
A7: AUTH-006 | B7: Authentication | C7: Login | D7: Empty password | E7: Validation | F7: P1 | G7: Anonymous | H7: - | I7: 1. Open /login 2. Enter email 3. Leave password empty 4. Sign In | J7: admin@company.com / '' | K7: Error 'Password is required'. | L7: backend src/services/auth/utils/validation.ts | M7: Not Run
A8: AUTH-007 | B8: Authentication | C8: Login | D8: Username that is not an email | E8: Validation | F8: P1 | G8: Anonymous | H8: - | I8: 1. Open /login 2. Enter text without @ 3. Enter password 4. Sign In | J8: adminuser / Test@1234 | K8: Error 'Username must be a valid email address'. | L8: backend src/services/auth/utils/validation.ts | M8: Not Run
A9: AUTH-008 | B9: Authentication | C9: Login | D9: Password shorter than 8 characters | E9: Validation | F9: P2 | G9: Anonymous | H9: - | I9: 1. Open /login 2. Enter valid email 3. Enter 7-char password 4. Sign In | J9: admin@company.com / Ab1cdef | K9: Request rejected by validation (minimum 8 characters). | L9: backend src/services/auth/utils/validation.ts | M9: Not Run
A10: AUTH-009 | B10: Authentication | C10: Login | D10: Password longer than 128 characters | E10: Edge | F10: P3 | G10: Anonymous | H10: - | I10: 1. Open /login 2. Enter valid email 3. Paste a 129-character password 4. Sign In | J10: 129 x 'A1b' | K10: Request rejected by validation (maximum 128 characters). | L10: backend src/services/auth/utils/validation.ts | M10: Not Run
A11: AUTH-010 | B11: Authentication | C11: Login | D11: Disabled (inactive) user cannot log in | E11: Negative | F11: P0 | G11: Employee | H11: User exists with password but is disabled by admin | I11: 1. Open /login 2. Enter the disabled user's credentials 3. Sign In | J11: disabled.user@company.com / Test@1234 | K11: Login is blocked; user account status is INACTIVE so canUserLogin is false. | L11: backend src/services/auth/utils/userAccountStatus.ts | M11: Pass | N11: Executed probe: Behaved as expected. Logic checked by running the backend code; UI / API / database flow NOT tested. | O11: Claude (auto) | P11: 2026-10-21
A12: AUTH-011 | B12: Authentication | C12: Login | D12: Invited user who has not set a password cannot log in | E12: Negative | F12: P0 | G12: Employee | H12: User created by admin; password not yet set (status PENDING) | I12: 1. Open /login 2. Enter the invited user's email and any password 3. Sign In | J12: new.hire@company.com / Test@1234 | K12: Login is blocked; account is PENDING until a password is set via invite link. | L12: backend src/services/auth/utils/userAccountStatus.ts | M12: Pass | N12: Executed probe: Behaved as expected. Logic checked by running the backend code; UI / API / database flow NOT tested. | O12: Claude (auto) | P12: 2026-10-21
A13: AUTH-012 | B13: Authentication | C13: Login | D13: Deleted user cannot log in | E13: Negative | F13: P0 | G13: Employee | H13: User is soft-deleted (deletedAt set) | I13: 1. Open /login 2. Enter the deleted user's credentials 3. Sign In | J13: deleted.user@company.com / Test@1234 | K13: Login is blocked; DELETED status wins over every other state. | L13: backend src/services/auth/utils/userAccountStatus.ts | M13: Pass | N13: Executed probe: Behaved as expected. Logic checked by running the backend code; UI / API / database flow NOT tested. | O13: Claude (auto) | P13: 2026-10-21
A14: AUTH-013 | B14: Authentication | C14: Login | D14: Login blocked when the user's company is inactive | E14: Negative | F14: P1 | G14: Employee | H14: Company is deactivated by Super Admin | I14: 1. Deactivate the company 2. Login as an employee of that company | J14: employee@inactive-co.com / Test@1234 | K14: Action blocked with message '<Company name> is inactive.' (or 'This company is inactive.'). | L14: backend src/services/company/utils/activityGuards.ts | M14: Not Run
A15: AUTH-014 | B15: Authentication | C15: Login | D15: Show/hide password toggle | E15: UI | F15: P3 | G15: Anonymous | H15: - | I15: 1. Open /login 2. Type a password 3. Click the eye icon | J15: any | K15: Password toggles between masked and visible text. | L15: frontend app/(authentication)/login/page.tsx | M15: Not Run
A16: AUTH-015 | B16: Authentication | C16: Login | D16: Protected page without a session redirects to login | E16: Permission | F16: P0 | G16: Anonymous | H16: Not logged in | I16: 1. Open /dashboard directly in a new browser profile | J16: - | K16: User is redirected to /login; no dashboard data shown. | L16: frontend app/dashboard | M16: Not Run
A17: AUTH-016 | B17: Authentication | C17: Session | D17: Logout clears session | E17: Positive | F17: P1 | G17: Employee | H17: Logged in | I17: 1. Click profile menu 2. Click Logout 3. Press browser Back | J17: - | K17: User returns to login; Back button does not reopen protected pages. | L17: frontend app/dashboard | M17: Not Run
A18: AUTH-017 | B18: Authentication | C18: Session | D18: Expired/invalid token is rejected by API | E18: Negative | F18: P0 | G18: Employee | H18: Logged in | I18: 1. Tamper with or expire the stored token 2. Refresh /dashboard | J18: token='abc.def.ghi' | K18: API returns unauthorized; user is sent to login. | L18: backend src/modules/config/authenticate.ts | M18: Not Run
A19: AUTH-018 | B19: Authentication | C19: Forgot Password | D19: Request reset link with registered email | E19: Positive | F19: P1 | G19: Anonymous | H19: Active user exists | I19: 1. Open /forgot-password 2. Enter registered email 3. Submit | J19: admin@company.com | K19: Success message shown; a reset email with a secure link is sent. | L19: backend src/services/auth/utils/validation.ts | M19: Not Run
A20: AUTH-019 | B20: Authentication | C20: Forgot Password | D20: Request reset with invalid email format | E20: Validation | F20: P2 | G20: Anonymous | H20: - | I20: 1. Open /forgot-password 2. Enter 'abc' 3. Submit | J20: abc | K20: Error 'Username should be a valid email address'. | L20: backend src/services/auth/utils/validation.ts | M20: Not Run
A21: AUTH-020 | B21: Authentication | C21: Forgot Password | D21: Request reset with empty email | E21: Validation | F21: P2 | G21: Anonymous | H21: - | I21: 1. Open /forgot-password 2. Leave empty 3. Submit | J21: '' | K21: Error 'Username is required'. | L21: backend src/services/auth/utils/validation.ts | M21: Not Run
A22: AUTH-021 | B22: Authentication | C22: Reset Password | D22: Reset password with valid token and strong password | E22: Positive | F22: P0 | G22: Anonymous | H22: Valid reset link received by email | I22: 1. Open the reset link 2. Enter a new strong password 3. Submit 4. Login with the new password | J22: NewPass@123 | K22: Password changes; old password stops working; login works with the new one. | L22: backend src/services/auth/utils/validation.ts | M22: Not Run
A23: AUTH-022 | B23: Authentication | C23: Reset Password | D23: Reset with expired/invalid token | E23: Negative | F23: P0 | G23: Anonymous | H23: Expired or random token | I23: 1. Open /reset-password/<bad-token> 2. Enter strong password 3. Submit | J23: token=invalid | K23: Reset rejected with an invalid/expired token error. | L23: backend src/services/auth/auth.service.ts | M23: Not Run
A24: AUTH-023 | B24: Authentication | C24: Reset Password | D24: Reset link cannot be reused | E24: Negative | F24: P1 | G24: Anonymous | H24: Reset already completed once | I24: 1. Use the same link again 2. Submit a new password | J24: - | K24: Second attempt is rejected. | L24: backend src/services/auth/auth.service.ts | M24: Not Run
A25: AUTH-024 | B25: Authentication | C25: Password Rules | D25: Weak password rejected (7 characters) | E25: Boundary | F25: P1 | G25: Anonymous | H25: Valid reset token | I25: 1. Open the reset page 2. Enter 'Pass123' 3. Submit | J25: Pass123 | K25: Password must contain at least 8 characters, including one uppercase letter, one lowercase letter, and one digit. | L25: backend src/services/auth/utils/validation.ts | M25: Not Run
... A48: EMP-007 | B48: Employees & Users | C48: Create Employee | D48: Employee role cannot open user management | E48: Permission | F48: P0 | G48: Employee | H48: Logged in as Employee | I48: 1. Open /dashboard/users directly | J48: - | K48: Access denied / redirected; no user list returned by API. | L48: frontend app/dashboard/users | M48: Not Run
A49: EMP-008 | B49: Employees & Users | C49: Employee Code | D49: Company code is normalized to upper case | E49: Positive | F49: P2 | G49: Company Admin | H49: - | I49: 1. Set company code ' acme ' 2. Save | J49: ' acme ' | K49: Saved as ACME. | L49: backend src/services/employeeCode/employeeCode.utils.ts | M49: Pass | N49: Executed probe: Behaved as expected. Logic checked by running the backend code; UI / API / database flow NOT tested. | O49: Claude (auto) | P49: 2026-10-21
A50: EMP-009 | B50: Employees & Users | C50: Employee Code | D50: Company code length 2 to 20 | E50: Boundary | F50: P2 | G50: Company Admin | H50: - | I50: 1. Try 'A' 2. 'AB' 3. 20 chars 4. 21 chars | J50: A / AB / 20 / 21 chars | K50: 'A' and 21 chars rejected; 'AB' and 20 chars accepted. | L50: backend src/services/employeeCode/employeeCode.utils.ts | M50: Pass | N50: Executed probe: Behaved as expected. Logic checked by running the backend code; UI / API / database flow NOT tested. | O50: Claude (auto) | P50: 2026-10-21
A51: EMP-010 | B51: Employees & Users | C51: Employee Code | D51: Company code allows only letters, digits and single hyphens | E51: Validation | F51: P2 | G51: Company Admin | H51: - | I51: 1. Try 'AC ME' 2. 'ACME-' 3. 'AC--ME' 4. 'AC-ME' | J51: as listed | K51: First three rejected; 'AC-ME' accepted. | L51: backend src/services/employeeCode/employeeCode.utils.ts | M51: Pass | N51: Executed probe: Behaved as expected. Logic checked by running the backend code; UI / API / database flow NOT tested. | O51: Claude (auto) | P51: 2026-10-21
A52: EMP-011 | B52: Employees & Users | C52: Employee Code | D52: Employee number max length 40 | E52: Boundary | F52: P2 | G52: HR | H52: - | I52: 1. Enter 40-char number 2. Enter 41-char number | J52: 40 / 41 chars | K52: 40 accepted; 41 rejected. | L52: backend src/services/employeeCode/employeeCode.utils.ts | M52: Pass | N52: Executed probe: Behaved as expected. Logic checked by running the backend code; UI / API / database flow NOT tested. | O52: Claude (auto) | P52: 2026-10-21
A53: EMP-012 | B53: Employees & Users | C53: Employee Code | D53: Employee ID is built as COMPANY-NUMBER | E53: Positive | F53: P1 | G53: HR | H53: Company code ACME | I53: 1. Create employee with number '0042' | J53: 0042 | K53: Employee ID shown as ACME-0042. | L53: backend src/services/employeeCode/employeeCode.utils.ts | M53: Pass | N53: Executed probe: {"companyCode":"ACME","employeeNumber":"0042","code":"ACME-0042"}. Logic checked by running the backend code; UI / API / database flow NOT tested. | O53: Claude (auto) | P53: 2026-10-21
A54: EMP-013 | B54: Employees & Users | C54: Employee Code | D54: Company prefix typed by user is not duplicated | E54: Edge | F54: P2 | G54: HR | H54: Company code ACME | I54: 1. Enter employee number 'acme-0042' | J54: acme-0042 | K54: ID is ACME-0042 (not ACME-ACME-0042). | L54: backend src/services/employeeCode/employeeCode.utils.ts | M54: Pass | N54: Executed probe: {"companyCode":"ACME","employeeNumber":"0042","code":"ACME-0042"}. Logic checked by running the backend code; UI / API / database flow NOT tested. | O54: Claude (auto) | P54: 2026-10-21
A55: EMP-014 | B55: Employees & Users | C55: Employee Code | D55: Employee number that only looks like the prefix is kept | E55: Edge | F55: P3 | G55: HR | H55: Company code ACME | I55: 1. Enter 'ACMEX-1' | J55: ACMEX-1 | K55: Stored as ACMEX-1 under ACME => ACME-ACMEX-1. | L55: backend src/services/employeeCode/employeeCode.utils.ts | M55: Pass | N55: Executed probe: {"companyCode":"ACME","employeeNumber":"ACMEX-1","code":"ACME-ACMEX-1"}. Logic checked by running the backend code; UI / API / database flow NOT tested. | O55: Claude (auto) | P55: 2026-10-21
A56: EMP-015 | B56: Employees & Users | C56: Employee Code | D56: Duplicate employee number in same company | E56: Negative | F56: P1 | G56: HR | H56: ACME-0042 exists | I56: 1. Create another employee with number 0042 | J56: 0042 | K56: Error 'Employee code already exists (ACME-0042)' naming the owner. | L56: backend src/services/adminUsers/adminUsers.service.ts | M56: Not Run
A57: EMP-016 | B57: Employees & Users | C57: Bulk Upload | D57: Download bulk upload template | E57: Positive | F57: P2 | G57: HR | H57: - | I57: 1. Users > Bulk upload 2. Click Download template | J57: - | K57: Excel template downloads with expected columns. | L57: backend src/routing (GET /bulk/template) | M57: Not Run
A58: EMP-017 | B58: Employees & Users | C58: Bulk Upload | D58: Preview then commit valid file | E58: Positive | F58: P1 | G58: HR | H58: Filled template with 5 valid rows | I58: 1. Upload file 2. Review preview 3. Commit | J58: 5 rows | K58: Preview shows 5 valid rows; commit creates 5 employees. | L58: backend src/routing (POST /bulk, /commit) | M58: Not Run
A59: EMP-018 | B59: Employees & Users | C59: Bulk Upload | D59: File with invalid rows | E59: Negative | F59: P1 | G59: HR | H59: File has 1 duplicate email and 1 missing name | I59: 1. Upload file 2. Review preview | J59: 2 bad rows | K59: Bad rows flagged with reasons; valid rows can still proceed or commit is blocked as designed. | L59: backend src/routing (POST /bulk) | M59: Not Run
A60: EMP-019 | B60: Employees & Users | C60: Bulk Upload | D60: Wrong file type | E60: Negative | F60: P2 | G60: HR | H60: - | I60: 1. Upload a .pdf as bulk file | J60: sample.pdf | K60: Rejected with a clear file-type error. | L60: frontend app/dashboard/users | M60: Not Run
A61: EMP-020 | B61: Employees & Users | C61: Status | D61: Disable an employee | E61: Positive | F61: P0 | G61: HR | H61: Active employee | I61: 1. Open employee 2. Click Disable 3. Confirm | J61: - | K61: Status becomes Inactive; employee can no longer log in. | L61: backend PUT /:id/status | M61: Not Run
A62: EMP-021 | B62: Employees & Users | C62: Status | D62: Re-enable an employee | E62: Positive | F62: P1 | G62: HR | H62: Disabled employee with password | I62: 1. Click Enable | J62: - | K62: Status returns to Active; login works. | L62: backend PUT /:id/status | M62: Not Run
...
